<?xml version="1.0" encoding="utf-8"?>
<!-- This URDF was automatically created by SolidWorks to URDF Exporter! Originally created by Stephen Brawner (brawner@gmail.com) 
     Commit Version: 1.6.0-4-g7f85cfe  Build Version: 1.6.7995.38578
     For more information, please see http://wiki.ros.org/sw_urdf_exporter -->
<robot
  name="drone">
  <link
    name="base_link">
    <inertial>
      <origin
        xyz="0.1358 0.10783 0.21694"
        rpy="0 0 0" />
      <mass
        value="0.49647" />
      <inertia
        ixx="0.00071849"
        ixy="3.6349E-09"
        ixz="-5.2575E-05"
        iyy="0.00090993"
        iyz="-2.4593E-08"
        izz="0.00071439" />
    </inertial>
    <visual>
      <origin
        xyz="0 0 0"
        rpy="0 0 0" />
      <geometry>
        <mesh
          filename="package://drone/meshes/base_link.STL" />
      </geometry>
      <material
        name="">
        <color
          rgba="0.79216 0.81961 0.93333 1" />
      </material>
    </visual>
    <collision>
      <origin
        xyz="0 0 0"
        rpy="0 0 0" />
      <geometry>
        <mesh
          filename="package://drone/meshes/base_link.STL" />
      </geometry>
    </collision>
  </link>
  <link
    name="Motor1">
    <inertial>
      <origin
        xyz="-0.0047604 -0.00018472 1.7423E-05"
        rpy="0 0 0" />
      <mass
        value="0.0055956" />
      <inertia
        ixx="3.3279E-06"
        ixy="1.1715E-11"
        ixz="1.2262E-10"
        iyy="3.2871E-06"
        iyz="-2.9847E-07"
        izz="1.4812E-07" />
    </inertial>
    <visual>
      <origin
        xyz="0 0 0"
        rpy="0 0 0" />
      <geometry>
        <mesh
          filename="package://drone/meshes/Motor1.STL" />
      </geometry>
      <material
        name="">
        <color
          rgba="0.79216 0.81961 0.93333 1" />
      </material>
    </visual>
    <collision>
      <origin
        xyz="0 0 0"
        rpy="0 0 0" />
      <geometry>
        <mesh
          filename="package://drone/meshes/Motor1.STL" />
      </geometry>
    </collision>
  </link>
  <joint
    name="Motor1_cont"
    type="continuous">
    <origin
      xyz="0.38789 -0.21724 0.17864"
      rpy="1.5708 -1.5708 0" />
    <parent
      link="base_link" />
    <child
      link="Motor1" />
    <axis
      xyz="1 0 0" />
  </joint>
  <link
    name="Motor2">
    <inertial>
      <origin
        xyz="-0.0047604 1.7423E-05 0.00018472"
        rpy="0 0 0" />
      <mass
        value="0.0055956" />
      <inertia
        ixx="3.3279E-06"
        ixy="1.2262E-10"
        ixz="-1.1715E-11"
        iyy="1.4812E-07"
        iyz="2.9847E-07"
        izz="3.2871E-06" />
    </inertial>
    <visual>
      <origin
        xyz="0 0 0"
        rpy="0 0 0" />
      <geometry>
        <mesh
          filename="package://drone/meshes/Motor2.STL" />
      </geometry>
      <material
        name="">
        <color
          rgba="0.79216 0.81961 0.93333 1" />
      </material>
    </visual>
    <collision>
      <origin
        xyz="0 0 0"
        rpy="0 0 0" />
      <geometry>
        <mesh
          filename="package://drone/meshes/Motor2.STL" />
      </geometry>
    </collision>
  </link>
  <joint
    name="Motor2_cont"
    type="continuous">
    <origin
      xyz="0.13639 -0.46874 0.17864"
      rpy="1.5708 -1.5708 0" />
    <parent
      link="base_link" />
    <child
      link="Motor2" />
    <axis
      xyz="1 0 0" />
  </joint>
  <link
    name="Motor3">
    <inertial>
      <origin
        xyz="-0.0047604 1.7423E-05 0.00018472"
        rpy="0 0 0" />
      <mass
        value="0.0055956" />
      <inertia
        ixx="3.3279E-06"
        ixy="1.2262E-10"
        ixz="-1.1715E-11"
        iyy="1.4812E-07"
        iyz="2.9847E-07"
        izz="3.2871E-06" />
    </inertial>
    <visual>
      <origin
        xyz="0 0 0"
        rpy="0 0 0" />
      <geometry>
        <mesh
          filename="package://drone/meshes/Motor3.STL" />
      </geometry>
      <material
        name="">
        <color
          rgba="0.79216 0.81961 0.93333 1" />
      </material>
    </visual>
    <collision>
      <origin
        xyz="0 0 0"
        rpy="0 0 0" />
      <geometry>
        <mesh
          filename="package://drone/meshes/Motor3.STL" />
      </geometry>
    </collision>
  </link>
  <joint
    name="Motor3_cont"
    type="continuous">
    <origin
      xyz="0.13639 0.034256 0.17864"
      rpy="1.5708 -1.5708 0" />
    <parent
      link="base_link" />
    <child
      link="Motor3" />
    <axis
      xyz="1 0 0" />
  </joint>
  <link
    name="Motor4">
    <inertial>
      <origin
        xyz="-0.0047604 1.7423E-05 0.00018472"
        rpy="0 0 0" />
      <mass
        value="0.0055956" />
      <inertia
        ixx="3.3279E-06"
        ixy="1.2262E-10"
        ixz="-1.1715E-11"
        iyy="1.4812E-07"
        iyz="2.9847E-07"
        izz="3.2871E-06" />
    </inertial>
    <visual>
      <origin
        xyz="0 0 0"
        rpy="0 0 0" />
      <geometry>
        <mesh
          filename="package://drone/meshes/Motor4.STL" />
      </geometry>
      <material
        name="">
        <color
          rgba="0.79216 0.81961 0.93333 1" />
      </material>
    </visual>
    <collision>
      <origin
        xyz="0 0 0"
        rpy="0 0 0" />
      <geometry>
        <mesh
          filename="package://drone/meshes/Motor4.STL" />
      </geometry>
    </collision>
  </link>
  <joint
    name="Motor4_cont"
    type="continuous">
    <origin
      xyz="-0.11511 -0.21724 0.17864"
      rpy="1.5708 -1.5708 0" />
    <parent
      link="base_link" />
    <child
      link="Motor4" />
    <axis
      xyz="1 0 0" />
  </joint>
</robot>